[2024-03-16T00:34:24.307-0400] {taskinstance.py:1979} INFO - Dependencies all met for dep_context=non-requeueable deps ti=<TaskInstance: PII_Data_Detection.load_data_from_gcp scheduled__2024-03-15T03:22:00+00:00 [queued]>
[2024-03-16T00:34:24.312-0400] {taskinstance.py:1979} INFO - Dependencies all met for dep_context=requeueable deps ti=<TaskInstance: PII_Data_Detection.load_data_from_gcp scheduled__2024-03-15T03:22:00+00:00 [queued]>
[2024-03-16T00:34:24.312-0400] {taskinstance.py:2193} INFO - Starting attempt 6 of 7
[2024-03-16T00:34:24.334-0400] {taskinstance.py:2217} INFO - Executing <Task(PythonOperator): load_data_from_gcp> on 2024-03-15 03:22:00+00:00
[2024-03-16T00:34:24.338-0400] {standard_task_runner.py:60} INFO - Started process 382852 to run task
[2024-03-16T00:34:24.341-0400] {standard_task_runner.py:87} INFO - Running: ['airflow', 'tasks', 'run', 'PII_Data_Detection', 'load_data_from_gcp', 'scheduled__2024-03-15T03:22:00+00:00', '--job-id', '322', '--raw', '--subdir', 'DAGS_FOLDER/src/airflow.py', '--cfg-path', '/tmp/tmpw8aq1hmg']
[2024-03-16T00:34:24.343-0400] {standard_task_runner.py:88} INFO - Job 322: Subtask load_data_from_gcp
[2024-03-16T00:34:24.390-0400] {task_command.py:423} INFO - Running <TaskInstance: PII_Data_Detection.load_data_from_gcp scheduled__2024-03-15T03:22:00+00:00 [running]> on host MSI.
[2024-03-16T00:34:24.461-0400] {taskinstance.py:2513} INFO - Exporting env vars: AIRFLOW_CTX_DAG_OWNER='airflow' AIRFLOW_CTX_DAG_ID='PII_Data_Detection' AIRFLOW_CTX_TASK_ID='load_data_from_gcp' AIRFLOW_CTX_EXECUTION_DATE='2024-03-15T03:22:00+00:00' AIRFLOW_CTX_TRY_NUMBER='6' AIRFLOW_CTX_DAG_RUN_ID='scheduled__2024-03-15T03:22:00+00:00'
[2024-03-16T00:34:24.462-0400] {logging_mixin.py:188} INFO - environment path is set
[2024-03-16T00:34:24.463-0400] {logging_mixin.py:188} INFO - current project directory /home/vineshgvk/PII-Data
[2024-03-16T00:34:24.463-0400] {logging_mixin.py:188} INFO - destination directory at /home/vineshgvk/PII-Data/dags/processed
[2024-03-16T00:34:24.463-0400] {logging_mixin.py:188} INFO - Trying to create a storage client connection
[2024-03-16T00:34:24.543-0400] {logging_mixin.py:188} INFO - Trying to fetch the specified bucket name
[2024-03-16T00:34:24.755-0400] {process_utils.py:131} INFO - Sending Signals.SIGTERM to group 382852. PIDs of all processes in the group: [382852]
[2024-03-16T00:34:24.757-0400] {process_utils.py:86} INFO - Sending the signal Signals.SIGTERM to group 382852
[2024-03-16T00:34:24.758-0400] {taskinstance.py:2483} ERROR - Received SIGTERM. Terminating subprocesses.
[2024-03-16T00:34:24.761-0400] {logging_mixin.py:188} INFO - An unexpected error occurred: Task received SIGTERM signal
[2024-03-16T00:34:24.762-0400] {python.py:202} INFO - Done. Returned value was: None
[2024-03-16T00:34:24.781-0400] {taskinstance.py:1149} INFO - Marking task as SUCCESS. dag_id=PII_Data_Detection, task_id=load_data_from_gcp, execution_date=20240315T032200, start_date=20240316T043424, end_date=20240316T043424
[2024-03-16T00:34:24.792-0400] {logging_mixin.py:188} WARNING - /home/vineshgvk/airflow_env/lib/python3.10/site-packages/airflow/utils/context.py:207 AirflowContextDeprecationWarning: Accessing 'execution_date' from the template is deprecated and will be removed in a future version. Please use 'data_interval_start' or 'logical_date' instead.
[2024-03-16T00:34:24.821-0400] {logging_mixin.py:188} WARNING - /home/vineshgvk/airflow_env/lib/python3.10/site-packages/airflow/utils/email.py:154 RemovedInAirflow3Warning: Fetching SMTP credentials from configuration variables will be deprecated in a future release. Please set credentials using a connection instead.
[2024-03-16T00:34:24.822-0400] {email.py:270} INFO - Email alerting: attempt 1
[2024-03-16T00:36:54.980-0400] {taskinstance.py:1127} ERROR - Error when executing task_success_alert callback
Traceback (most recent call last):
  File "/home/vineshgvk/airflow_env/lib/python3.10/site-packages/airflow/models/taskinstance.py", line 1124, in _run_finished_callback
    callback(context)
  File "/home/vineshgvk/PII-Data/dags/src/airflow.py", line 200, in task_success_alert
    send_email(to='gvk7663@gmail.com', subject=subject, html_content=html_content)
  File "/home/vineshgvk/airflow_env/lib/python3.10/site-packages/airflow/utils/email.py", line 80, in send_email
    return backend(
  File "/home/vineshgvk/airflow_env/lib/python3.10/site-packages/airflow/utils/email.py", line 154, in send_email_smtp
    send_mime_email(e_from=mail_from, e_to=recipients, mime_msg=msg, conn_id=conn_id, dryrun=dryrun)
  File "/home/vineshgvk/airflow_env/lib/python3.10/site-packages/airflow/utils/email.py", line 272, in send_mime_email
    smtp_conn = _get_smtp_connection(smtp_host, smtp_port, smtp_timeout, smtp_ssl)
  File "/home/vineshgvk/airflow_env/lib/python3.10/site-packages/airflow/utils/email.py", line 316, in _get_smtp_connection
    return smtplib.SMTP(host=host, port=port, timeout=timeout)
  File "/usr/lib/python3.10/smtplib.py", line 255, in __init__
    (code, msg) = self.connect(host, port)
  File "/usr/lib/python3.10/smtplib.py", line 341, in connect
    self.sock = self._get_socket(host, port, self.timeout)
  File "/usr/lib/python3.10/smtplib.py", line 312, in _get_socket
    return socket.create_connection((host, port), timeout,
  File "/usr/lib/python3.10/socket.py", line 845, in create_connection
    raise err
  File "/usr/lib/python3.10/socket.py", line 833, in create_connection
    sock.connect(sa)
OSError: [Errno 101] Network is unreachable
