[2024-03-16T00:47:03.033-0400] {scheduler_job_runner.py:781} ERROR - Executor reports task instance <TaskInstance: PII_Data_Detection.load_data_from_gcp scheduled__2024-03-15T05:26:00+00:00 [queued]> finished (failed) although the task says it's queued. (Info: None) Was the task killed externally?
